Workbook

Sheet IBC (NEW)
B1: ALPHA START LIMITED | H1: ='CUSTOM INVOICE'!C11 -> EPIC GARMENTS MANUFACTURING CO.LTD.,(UNIT-2)
B2: =+'CUSTOM INVOICE'!E2 -> 7/F, EGL TOWER | H2: ='CUSTOM INVOICE'!C12 -> SFB NO.08 (GROUND, 1ST,2ND,3RD & 4TH FLOOR)
B3: =+'CUSTOM INVOICE'!E3 -> 83 HUNG TO ROAD, KWUN TONG | H3: ='CUSTOM INVOICE'!C13 -> DEPZ EXTENSION AREA, GONOK BARI, SAVAR,
B4: =+'CUSTOM INVOICE'!E4 -> KOWLOON, HONG KONG. | H4: ATTN: PRIYANTHA
B7: RUWAN | E7: 3512 0800
E15: =+'CUSTOM INVOICE'!B25 -> 1 | F15: PKG(S) | H15: ACCESSORIES
H16: INVOICE NO. | I16: ='CUSTOM INVOICE'!D23 -> S/ 5157 /26
H17: SAMPLE OF NO COMMERCIAL VALUE
B26: =TODAY() -> 46301

Sheet UTC
B2: ALPHA START LIMITED | G2: TO : UNION TRAVEL COMPANY
B3: =+'CUSTOM INVOICE'!E2 -> 7/F, EGL TOWER | G3: DATE : | I3: =TODAY()+H12 -> 46301
B4: =+'CUSTOM INVOICE'!E3 -> 83 HUNG TO ROAD, KWUN TONG
B5: =+'CUSTOM INVOICE'!E4 -> KOWLOON, HONG KONG.
E6: 3512 0800
B8: ='CUSTOM INVOICE'!C11 -> EPIC GARMENTS MANUFACTURING CO.LTD.,(UNIT-2)
B9: ='CUSTOM INVOICE'!C12 -> SFB NO.08 (GROUND, 1ST,2ND,3RD & 4TH FLOOR)
B10: ='CUSTOM INVOICE'!C13 -> DEPZ EXTENSION AREA, GONOK BARI, SAVAR,
B11: ='CUSTOM INVOICE'!E14 -> 0
I13: XX
B15: SAME AS CONSIGNEE
I16: XX
D22: HONGKONG
B23: DHAKA | D23: XXX | H23: ATTACHED INVOICE, PACKING LIST
D27: TOTAL : | E27: =+'CUSTOM INVOICE'!B25 -> 1 | F27: =+'CUSTOM INVOICE'!C25 -> PKG(S) ONLY. | J27: ** FREIGHT PREPAID **
B31: =+'CUSTOM INVOICE'!J9 -> EGMCL-FOC
B32: =+'CUSTOM INVOICE'!J10 -> DHAKA, BD | E32: KOHL'S MISSY 10 FULL FORM
E33: DUMMY
E39: =+'CUSTOM INVOICE'!A40 -> TIN # 211-201-7957/Coy-20
E40: SAMPLE OF NO COMMERCIAL VALUE

Sheet JANCO
A1: SHIPPER’S AIR SHIPMENT INSTRUCTIONS TO ARRANGE FOR SHIPMENTS OF GOODS
A2: From Shipper (“The Customer”) | E2: To The Agent | H2: Export Licence no.
A3: ALPHA START LTD.
A4: 7TH FLOOR.,EGL TOWER,
A5: 83 HUNG TO ROAD, | H5: Cert. of Origin no.
A6: KWUN TONG, KOWLOON, HONG KONG
A7: Business Reg. no. Tel no.:
A8: Consignee | E8: JANCO INTERNATIONAL FREIGHT LTD.
A9: =+'CUSTOM INVOICE'!C11 -> EPIC GARMENTS MANUFACTURING CO.LTD.,(UNIT-2)
A10: =+'CUSTOM INVOICE'!C12 -> SFB NO.08 (GROUND, 1ST,2ND,3RD & 4TH FLOOR) | E10: AIR DEPT: TEL: 21495783 / FAX: 25129179
A11: =+'CUSTOM INVOICE'!C13 -> DEPZ EXTENSION AREA, GONOK BARI, SAVAR, | E11: ATTN: ANDY / SUNNY
A12: =+UTC!B11 -> 0
A13: Tel no.
A14: Notify Party : | E14: Airfreight
A15: SAME AS CONSIGNEE | E15: Charges □ To be prepaid □ To be collected
E16: (if services available)
E18: Other Charge
A19: MAWB NO. | C19: HAWB NO. | E19: ………………………. □ To be prepaid □ To be collected
E20: Country of Origin (Goods)
A21: Name of Carrier | C21: Departures Airport HONG KONG
E22: Booking No. JIF-60547
A23: Destination DHAKA | C23: Airline Counter Signature
C24: □ Yes □ No
A25: Marks & Nos: No. and Kind of Packages, Description of Goods
C27: TOTAL : | D27: =+'CUSTOM INVOICE'!B25 -> 1 | E27: PACKAGE(S) ONLY | I27: "FREIGHT PREPAID"
A29: =+'CUSTOM INVOICE'!J9 -> EGMCL-FOC | D29: FABRIC AND ACCESSORIES
A30: =+'CUSTOM INVOICE'!J10 -> DHAKA, BD
A31: =+'CUSTOM INVOICE'!H13 | D31: =+'CUSTOM INVOICE'!A40 -> TIN # 211-201-7957/Coy-20
A33: =+'CUSTOM INVOICE'!H13
A44: Specify Currency | B44: Declared Value for Customs | D44: Declared Value for Carriage | E44: Insurance Amount | H44: Shipper’s C.O.D.
A46: Documents to accompany airwaybill or house airwaybill ………………………………………………………………
A47: Packing List □ Commercial Invoice □ Certificate of Origin □ Form A □
A48: 倉庫地址WAREHOUSE ADDRESS: | E48: Signatory’s Name in Block Letter
A49: 永捷倉庫 : 香港新界葵涌, 貨櫃碼頭路 18 號, | B49: 永捷倉庫 : 香港新界葵涌, 貨櫃碼頭路 18 號, | C49: 永捷倉庫 : 香港新界葵涌, 貨櫃碼頭路 18 號, | D49: 永捷倉庫 : 香港新界葵涌, 貨櫃碼頭路 18 號,
A50: 葵涌四號貨櫃碼頭, 和黃物流中心 1樓, 101室 | B50: 葵涌四號貨櫃碼頭, 和黃物流中心 1樓, 101室 | C50: 葵涌四號貨櫃碼頭, 和黃物流中心 1樓, 101室 | D50: 葵涌四號貨櫃碼頭, 和黃物流中心 1樓, 101室
A51: (電話: 26152330/傳真: 21495083)
A52: 辦公時間 : 星期一至六 - 上午九時至下午六時
A53: Wings Warehouse: Unit 101, 1/F., Hutchsion Logistics Centre, | E53: Signature & Stamps
A54: Terminal 4, Kwai Chung Container Port, 18 Container
A55: Port Road South, Kwai Chung.
...

Sheet CUSTOM  INVOICE
E1: ALPHA START LIMITED
E2: 7/F, EGL TOWER
E3: 83 HUNG TO ROAD, KWUN TONG
E4: KOWLOON, HONG KONG.
E5: TEL: 3512 0800 FAX: 2345 8558
E7: CUSTOMS INVOICE & PACKING LIST
A9: DATE OF EXPORTATION : | D9: =TODAY() -> 46301 | G9: SHIPPING MARKS : | J9: EGMCL-FOC
J10: DHAKA, BD
A11: CONSIGNEE : | C11: EPIC GARMENTS MANUFACTURING CO.LTD.,(UNIT-2)
C12: SFB NO.08 (GROUND, 1ST,2ND,3RD & 4TH FLOOR)
C13: DEPZ EXTENSION AREA, GONOK BARI, SAVAR,
C14: DHAKA-1349, BANGLADESH.
C15: (BIN:000320579-0403)
A19: COUNTRY OF ULTIMATE DESTINATION : | E19: BANGLADESH
A21: Import open cover note # GDI/DEZ/07/2019/MAR/C/001352 (OPEN) Dated 03-JUL-2019
A23: CUSTOMS INVOICE NO. | D23: S/ 5157 /26
A25: TOTAL : | B25: 1 | C25: PKG(S) ONLY. | E25: GW: | F25: 1 | G25: KGS
A27: C/NO. | B27: DESCRIPTION OF GOODS | F27: QUANTITY
A31: 1 PKGS | B31: FABRIC SWATCHES | F31: 6 | G31: PCS
E36: TOTAL VALUE: | F36: 1
A40: TIN # 211-201-7957/Coy-20
A42: SAMPLE OF NO COMMERCIAL VALUE
A43: INVOICE ONLY FOR CUSTOMS PURPOSE

Sheet YMX
E6: MAY KWOK | I6: =+'CUSTOM INVOICE'!B25 -> 1
C7: =+'CUSTOM INVOICE'!D23 -> S/ 5157 /26
B9: =+'CUSTOM INVOICE'!E1 -> ALPHA START LIMITED
H10: ACCESSORIES
B11: =+'CUSTOM INVOICE'!E2 -> 7/F, EGL TOWER | H11: =+'CUSTOM INVOICE'!A42 -> SAMPLE OF NO COMMERCIAL VALUE
B12: =+'CUSTOM INVOICE'!E3 -> 83 HUNG TO ROAD, KWUN TONG
B13: =+'CUSTOM INVOICE'!E4 -> KOWLOON, HONG KONG.
E17: 852 35120800
A20: =+'CUSTOM INVOICE'!C11 -> EPIC GARMENTS MANUFACTURING CO.LTD.,(UNIT-2)
A23: =+'CUSTOM INVOICE'!C12 -> SFB NO.08 (GROUND, 1ST,2ND,3RD & 4TH FLOOR)
A24: =+'CUSTOM INVOICE'!C13 -> DEPZ EXTENSION AREA, GONOK BARI, SAVAR,
A25: =+'CUSTOM INVOICE'!C14 -> DHAKA-1349, BANGLADESH. | E25: =+'CUSTOM INVOICE'!C15 -> (BIN:000320579-0403)
A26: ATTN: ABUL KALAM AZAD / MOHAMMAD MASUD
A27: TEL: 880-9611008899
N31: =+'CUSTOM INVOICE'!D9 -> 46301

Sheet JANCO EXPRESS
D1: ALP00001
A6: ALP00001 | E6: RAJ
B7: =+'CUSTOM INVOICE'!D23 -> S/ 5157 /26
I8: =+'CUSTOM INVOICE'!B25 -> 1
B9: =+'CUSTOM INVOICE'!E1 -> ALPHA START LIMITED
B11: =+'CUSTOM INVOICE'!E2 -> 7/F, EGL TOWER
B12: =+'CUSTOM INVOICE'!E3 -> 83 HUNG TO ROAD, KWUN TONG
B13: =+'CUSTOM INVOICE'!E4 -> KOWLOON, HONG KONG.
H14: ACCESSORIES
H15: =+'CUSTOM INVOICE'!A42 -> SAMPLE OF NO COMMERCIAL VALUE
E17: 852 35120800
A20: =+'CUSTOM INVOICE'!C11 -> EPIC GARMENTS MANUFACTURING CO.LTD.,(UNIT-2)
A23: =+'CUSTOM INVOICE'!C12 -> SFB NO.08 (GROUND, 1ST,2ND,3RD & 4TH FLOOR)
A24: =+'CUSTOM INVOICE'!C13 -> DEPZ EXTENSION AREA, GONOK BARI, SAVAR,
A25: =+'CUSTOM INVOICE'!C14 -> DHAKA-1349, BANGLADESH.
A26: =+'CUSTOM INVOICE'!C15 -> (BIN:000320579-0403)
A27: ATTN : MR. KABIR / ALAM
N32: =+'CUSTOM INVOICE'!D9 -> 46301

Sheet KLT
G4: =+'CUSTOM INVOICE'!B25 -> 1 | H4: PKG(S) ONLY.
B6: ALPHA START LIMITED | G6: =+'CUSTOM INVOICE'!C11 -> EPIC GARMENTS MANUFACTURING CO.LTD.,(UNIT-2)
B8: MAY KWOK | G8: MR. KABIR / ALAM
B9: =+'CUSTOM INVOICE'!E2 -> 7/F, EGL TOWER | G9: =+'CUSTOM INVOICE'!C12 -> SFB NO.08 (GROUND, 1ST,2ND,3RD & 4TH FLOOR)
B10: =+'CUSTOM INVOICE'!E3 -> 83 HUNG TO ROAD, KWUN TONG | G10: =+'CUSTOM INVOICE'!C13 -> DEPZ EXTENSION AREA, GONOK BARI, SAVAR,
B11: =+'CUSTOM INVOICE'!E4 -> KOWLOON, HONG KONG. | G11: =+'CUSTOM INVOICE'!C14 -> DHAKA-1349, BANGLADESH.
G12: =+'CUSTOM INVOICE'!C15 -> (BIN:000320579-0403)
B14: 3512 0800
B17: ACCESSORIES/FABRIC
B18: =+'CUSTOM INVOICE'!A42 -> SAMPLE OF NO COMMERCIAL VALUE
B19: INVOICE NO. | D19: =+'CUSTOM INVOICE'!D23 -> S/ 5157 /26
B28: =+'CUSTOM INVOICE'!D9 -> 46301

Sheet DREAMCO
B2: ALPHA START LIMITED
B3: =+'CUSTOM INVOICE'!E2 -> 7/F, EGL TOWER | G3: =+'CUSTOM INVOICE'!C11 -> EPIC GARMENTS MANUFACTURING CO.LTD.,(UNIT-2)
B4: =+'CUSTOM INVOICE'!E3 -> 83 HUNG TO ROAD, KWUN TONG | G4: =+'CUSTOM INVOICE'!C12 -> SFB NO.08 (GROUND, 1ST,2ND,3RD & 4TH FLOOR)
B5: =+'CUSTOM INVOICE'!E4 -> KOWLOON, HONG KONG. | G5: =+'CUSTOM INVOICE'!C13 -> DEPZ EXTENSION AREA, GONOK BARI, SAVAR,
G6: =+'CUSTOM INVOICE'!C14 -> DHAKA-1349, BANGLADESH.
G7: =+'CUSTOM INVOICE'!C15 -> (BIN:000320579-0403)
B8: RAJ | E8: 3512 0800 | G8: ATTN : MR. KABIR / ALAM
D16: =+'CUSTOM INVOICE'!B25 -> 1 | E16: PKG(S) | F16: TRIM CARD
F17: SAMPLE OF NO COMMERCIAL VALUE
B18: ='CUSTOM INVOICE'!D9 -> 46301 | F18: INVOICE NO. | H18: =+'CUSTOM INVOICE'!D23 -> S/ 5157 /26

Sheet ROYALE 
B7: ALPHA START LIMITED
B9: 7/F, EGL TOWER,
B10: 83 HUNG TO ROAD, KWUN TONG
B11: KOWLOON, HONGKONG
F12: =+'CUSTOM INVOICE'!B25 -> 1 | G12: PKG(S) ONLY
B16: 35120800
B17: ROHAN
B18: =+'CUSTOM INVOICE'!D23 -> S/ 5157 /26 | E18: FABRICS/ACCESSORIES
E19: SAMPLE OF NO COMMERCIAL VALUE
E20: "FREIGHT PREPAID"
B24: =+'CUSTOM INVOICE'!C11 -> EPIC GARMENTS MANUFACTURING CO.LTD.,(UNIT-2)
A25: =+'CUSTOM INVOICE'!C12 -> SFB NO.08 (GROUND, 1ST,2ND,3RD & 4TH FLOOR)
A26: =+'CUSTOM INVOICE'!C13 -> DEPZ EXTENSION AREA, GONOK BARI, SAVAR,
H30: =+'CUSTOM INVOICE'!D9 -> 46301
B33: MR. SAROJ / ALAM

Sheet RPX 
E3: =+'CUSTOM INVOICE'!D23 -> S/ 5157 /26 | G3: =+'CUSTOM INVOICE'!C11 -> EPIC GARMENTS MANUFACTURING CO.LTD.,(UNIT-2)
B5: ALPHA START LIMITED | G5: =CONCATENATE('CUSTOM INVOICE'!C12,'CUSTOM INVOICE'!C13,'CUSTOM INVOICE'!E14) -> SFB NO.08 (GROUND, 1ST,2ND,3RD & 4TH FLOOR)DEPZ EXTENSION AREA, GONOK BARI, SAVAR,
B6: =+'CUSTOM INVOICE'!E2 -> 7/F, EGL TOWER
B7: =+'CUSTOM INVOICE'!E3 -> 83 HUNG TO ROAD, KWUN TONG
B8: =+'CUSTOM INVOICE'!E4 -> KOWLOON, HONG KONG.
G9: ATTN : MR. SAROJ / ALAM
G11: "FREIGHT PREPAID"
B13: ROHAN | E13: 35120800
A15: =+'CUSTOM INVOICE'!B25 -> 1 | B15: PKG(S)
E20: =+'CUSTOM INVOICE'!D9 -> 46301
A23: FABRICS & ACCESSORIES
A24: SAMPLE OF NO COMMERICAL VALUE
